{
  size: [3,4,3],
  data: [
    {state: "minecraft:bricks{weathering:false}",pos: [0,0,0]},
    {state: "minecraft:bricks{weathering:false}",pos: [0,0,2]},
    {state: "minecraft:bricks{weathering:false}",pos: [1,0,1]},
    {state: "minecraft:bricks{weathering:false}",pos: [2,0,0]},
    {state: "minecraft:bricks{weathering:false}",pos: [2,0,2]},
    {state: "minecraft:bricks{weathering:false}",pos: [0,1,0]},
    {state: "minecraft:bricks{weathering:false}",pos: [0,1,1]},
    {state: "minecraft:bricks{weathering:false}",pos: [0,1,2]},
    {state: "minecraft:bricks{weathering:false}",pos: [1,1,0]},
    {state: "minecraft:bricks{weathering:false}",pos: [1,1,1]},
    {state: "minecraft:bricks{weathering:false}",pos: [1,1,2]},
    {state: "minecraft:bricks{weathering:false}",pos: [2,1,0]},
    {state: "minecraft:bricks{weathering:false}",pos: [2,1,1]},
    {state: "minecraft:bricks{weathering:false}",pos: [2,1,2]},
    {state: "minecraft:bricks{weathering:false}",pos: [0,2,1]},
    {state: "minecraft:bricks{weathering:false}",pos: [1,2,0]},
    {state: "minecraft:bricks{weathering:false}",pos: [1,2,1]},
    {state: "minecraft:bricks{weathering:false}",pos: [1,2,2]},
    {state: "minecraft:bricks{weathering:false}",pos: [2,2,1]},
    {state: "minecraft:bricks{weathering:false}",pos: [1,3,1]},
    {state: "minecraft:brick_wall{waterlogged:false,up:true,west:none,weathering:false,east:low,south:low,north:none}",pos: [0,2,0]},
    {state: "minecraft:brick_wall{waterlogged:false,up:true,west:none,weathering:false,east:low,south:none,north:low}",pos: [0,2,2]},
    {state: "minecraft:brick_wall{waterlogged:false,up:true,west:low,weathering:false,east:none,south:low,north:none}",pos: [2,2,0]},
    {state: "minecraft:brick_wall{waterlogged:false,up:true,west:low,weathering:false,east:none,south:none,north:low}",pos: [2,2,2]},
    {state: "minecraft:brick_wall{waterlogged:false,up:true,west:none,weathering:false,east:none,south:none,north:none}",pos: [0,3,0]},
    {state: "minecraft:brick_stairs{waterlogged:false,half:bottom,facing:east,weathering:false,shape:straight}",pos: [0,3,1]},
    {state: "minecraft:brick_wall{waterlogged:false,up:true,west:none,weathering:false,east:none,south:none,north:none}",pos: [0,3,2]},
    {state: "minecraft:brick_stairs{waterlogged:false,half:bottom,facing:south,weathering:false,shape:straight}",pos: [1,3,0]},
    {state: "minecraft:brick_stairs{waterlogged:false,half:bottom,facing:north,weathering:false,shape:straight}",pos: [1,3,2]},
    {state: "minecraft:brick_wall{waterlogged:false,up:true,west:none,weathering:false,east:none,south:none,north:none}",pos: [2,3,0]},
    {state: "minecraft:brick_stairs{waterlogged:false,half:bottom,facing:west,weathering:false,shape:straight}",pos: [2,3,1]},
    {state: "minecraft:brick_wall{waterlogged:false,up:true,west:none,weathering:false,east:none,south:none,north:none}",pos: [2,3,2]},
    {state: "mm:kiln_fluid_output",pos: [0,0,1],nbt: {ForgeCaps: {},id: "mm:kiln_fluid_output",MMStorage: {handler: [{Amount: 0,FluidName: "minecraft:empty"}]}}},
    {state: "mm:kiln_item_input",pos: [1,0,0],nbt: {ForgeCaps: {},id: "mm:kiln_item_input",MMStorage: {handler: [{id: "minecraft:air",tag: {},Count: 0},{id: "minecraft:air",tag: {},Count: 0},{id: "minecraft:air",tag: {},Count: 0}]}}},
    {state: "mm:kiln_item_output",pos: [1,0,2],nbt: {ForgeCaps: {},id: "mm:kiln_item_output",MMStorage: {handler: [{id: "minecraft:air",tag: {},Count: 0},{id: "minecraft:air",tag: {},Count: 0},{id: "minecraft:air",tag: {},Count: 0}]}}},
    {state: "mm:kiln{facing:west}",pos: [2,0,1],nbt: {filler: 1b,ForgeCaps: {},id: "mm:kiln",structureId: "rololo:kiln"}}
  ],
  palette: [
    "minecraft:bricks{weathering:false}",
    "minecraft:brick_wall{waterlogged:false,up:true,west:none,weathering:false,east:low,south:low,north:none}",
    "minecraft:brick_wall{waterlogged:false,up:true,west:none,weathering:false,east:low,south:none,north:low}",
    "minecraft:brick_wall{waterlogged:false,up:true,west:low,weathering:false,east:none,south:low,north:none}",
    "minecraft:brick_wall{waterlogged:false,up:true,west:low,weathering:false,east:none,south:none,north:low}",
    "minecraft:brick_wall{waterlogged:false,up:true,west:none,weathering:false,east:none,south:none,north:none}",
    "minecraft:brick_stairs{waterlogged:false,half:bottom,facing:east,weathering:false,shape:straight}",
    "minecraft:brick_stairs{waterlogged:false,half:bottom,facing:south,weathering:false,shape:straight}",
    "minecraft:brick_stairs{waterlogged:false,half:bottom,facing:north,weathering:false,shape:straight}",
    "minecraft:brick_stairs{waterlogged:false,half:bottom,facing:west,weathering:false,shape:straight}",
    "mm:kiln_fluid_output",
    "mm:kiln_item_input",
    "mm:kiln_item_output",
    "mm:kiln{facing:west}"
  ],
  entities: [],
  DataVersion: 3337
}